Workbook

Sheet Dashboard
B1: AEC Strategy Implementation
B2: 2025/2026 Dashboard
B3: 1ST JAN 2026 TO 30TH SEPT 2026
B5: Focus Area | C5: Total Outcomes | D5: Total Milestones | E5: % Complete
B6: ='Data (Master Table)'!W3 -> Financial Stability | C6: =COUNTIF('Data (Master Table)'!C3:C17, "YES") -> 4 | D6: =SUM('Financial Stability'!L:L) -> 6 | E6: =AVERAGE('Financial Stability'!R:R) -> 0.65
B7: ='Data (Master Table)'!W4 -> Youth Succession Planning | C7: =COUNTIF('Data (Master Table)'!C18:C32, "YES") -> 6 | D7: =SUM('Youth Succession Planning'!L:L) -> 34 | E7: =AVERAGE('Youth Succession Planning'!R:R) -> 0.53333333
B8: ='Data (Master Table)'!W5 -> Wider Community Engagement | C8: =COUNTIF('Data (Master Table)'!C33:C47, "YES") -> 7 | D8: =SUM('Wider Community Engagement'!L:L) -> 24 | E8: =AVERAGE('Wider Community Engagement'!R:R) -> 0.55714286
B9: ='Data (Master Table)'!W6 -> Building Teams & Leadership | C9: =COUNTIF('Data (Master Table)'!C48:C62, "YES") -> 4 | D9: =SUM('Building Teams & Leadership'!L:L) -> 12 | E9: =AVERAGE('Building Teams & Leadership'!R:R) -> 0.55
B10: ='Data (Master Table)'!W7 -> Community Activities | C10: =COUNTIF('Data (Master Table)'!C63:C77, "YES") -> 3 | D10: =SUM('Community Activities'!L:L) -> 12 | E10: =AVERAGE('Community Activities'!R:R) -> 0.7
B11: ='Data (Master Table)'!W8 -> Spiritual Focus | C11: =COUNTIF('Data (Master Table)'!C78:C91, "YES") -> 6 | D11: =SUM('Spiritual Focus'!L:L) -> 13 | E11: =AVERAGE('Spiritual Focus'!R:R) -> 0.64
B12: TOTAL | C12: =SUM(C6:C11) -> 30 | D12: =SUM(D6:D11) -> 101 | E12: =AVERAGE(E6:E11) -> 0.60507937

Sheet Instructions
A1: Tracker Instructions
A3: Purpose
A4: This workbook tracks delivery of AEC’s 2025–2026 strategy across six focus areas. All stakeholders can see the whole spreadsheet; please edit your own tab only
A6: How to update
A7: 1) Click on your focus-area tab, adjust % bottom left to enable seeing all sections
A8: 2) Scroll down to see all streams. Add notes and modify sections as required; milestones, dates, owners etc.
A9: Grey cells and risk levels are not to be changed, white cells can be amended by you. Some cells (status, % and risk cells) have drop down boxes for you to select options
A10: 3) Set Status and % Complete using drop down boxes
A11: 4) If actions are delayed, choose a Reason for Delay and add a brief note
A12: 5) When finished just close the spreadsheet, it is automatically saved. Cancel changes you made by using the Und button in the home tab of the spreadsheet. The Dashboard will update your completion % automatically
A13: 6) The Dashboard will update your completion % automatically
A15: This video shows how to use the spreadsheet: | G15: Watch Video
A17: Please note: this document and the video are Confidential – Al‑Emaan Centre Internal Use Only. Not to be shared

Sheet Financial Stability
A1: ULTIMATE AIM : ESTABLISH DIVERSIFIED, SUSTAINABLE INCOME STREAMS SLT Lead Behzat | K1: ='Data (Master Table)'!W3 -> Financial Stability
A2: ='Data (Master Table)'!C2 -> IS VALID | B2: ='Data (Master Table)'!D2 -> SMART Outcome | C2: ='Data (Master Table)'!E2 -> Benefit | D2: ='Data (Master Table)'!F2 -> Starting Point / Baseline | E2: ='Data (Master Table)'!G2 -> Department | F2: ='Data (Master Table)'!H2 -> Reported to OPEX | G2: ='Data (Master Table)'!I2 -> Responsible Person | H2: ='Data (Master Table)'!J2 -> Risk Level | ... S2: ='Data (Master Table)'!U2 -> Notes
A3: =IF('Data (Master Table)'!$B3 = $K$1, 'Data (Master Table)'!C3, "") -> YES | B3: =IF('Data (Master Table)'!$B3 = $K$1, 'Data (Master Table)'!D3, "") -> Establish diversified, sustainable income streams | C3: =IF('Data (Master Table)'!$B3 = $K$1, 'Data (Master Table)'!E3, "") -> Service provision, significant income stream to be invested in Waqf | D3: =IF('Data (Master Table)'!$B3 = $K$1, 'Data (Master Table)'!F3, "") -> Donation-dependent operations; limited reserves; no diversified income operational yet. Soft launch of TFS complete | E3: =IF('Data (Master Table)'!$B3 = $K$1, 'Data (Master Table)'!G3, "") -> Safa Holdings / Finance | F3: =IF('Data (Master Table)'!$B3 = $K$1, 'Data (Master Table)'!H3, "") -> End of March End of June End of Sept | G3: =IF('Data (Master Table)'!$B3 = $K$1, 'Data (Master Table)'!I3, "") -> Shaffiq | H3: =IF('Data (Master Table)'!$B3 = $K$1, 'Data (Master Table)'!J3, "") -> Medium | ... J3: =IF('Data (Master Table)'!$B3 = $K$1, 'Data (Master Table)'!L3, "") -> 46081 | K3: Deliver a live Funeral Service: Tahreem Funeral Service (operational & marketed) | L3: 3 | M3: 1. Cement policies & procedures 2. Hard Launch 3. Full service provision + £ | N3: 1. Jan - March 2. March 3. Mar - Sept | O3: Continuous service improvement, additional fridge set up. Imam and Funeral Director to run roadshow prior to hard launch. Thorough marketing and relationship building- cemeteries, hospitals etc. Add our website link to other masajid and Eternal Gardens website | P3: Complete | R3: 1 | S3: The launch included delivering 21 full funerals, tightening policies and procedures, adding fridges, creating leaflets, livening the website, sending emails and WhatsApp messages, building relationships with Shirley, Penge, Purley, MCWAS, Tunbridge Wells and Maidstone (including use of facilities at Maidstone and TW). Send messages to our community, making a popup for the AEC website, setting up Tahreem@group email, adding our details to the Eternal Gardens website, announcing at jumu'ah. Before hard laucnh we have made a net profit of £20k
A4: =IF('Data (Master Table)'!$B4 = $K$1, 'Data (Master Table)'!C4, "") -> YES | B4: =IF('Data (Master Table)'!$B4 = $K$1, 'Data (Master Table)'!D4, "") -> Establish diversified, sustainable income streams | C4: =IF('Data (Master Table)'!$B4 = $K$1, 'Data (Master Table)'!E4, "") -> Service provision, recurring advertising revenue + partnerships | D4: =IF('Data (Master Table)'!$B4 = $K$1, 'Data (Master Table)'!F4, "") -> Donation-dependent operations; limited reserves; no diversified income operational yet. Idea and website ready for Business Directory | E4: =IF('Data (Master Table)'!$B4 = $K$1, 'Data (Master Table)'!G4, "") -> Safa Holdings / Finance | F4: =IF('Data (Master Table)'!$B4 = $K$1, 'Data (Master Table)'!H4, "") -> End of March End of June End of Sept | G4: Shaffiq | H4: =IF('Data (Master Table)'!$B4 = $K$1, 'Data (Master Table)'!J4, "") -> Medium | I4: =IF('Data (Master Table)'!$B4 = $K$1, 'Data (Master Table)'!K4, "") -> Medium | J4: =IF('Data (Master Table)'!$B4 = $K$1, 'Data (Master Table)'!L4, "") -> 46112 | K4: Launch Green Pages Business Directory (100+ listings.) Launch through MosqueApp | L4: 1 | M4: Created website offering, Raja to launch and do intital pre registration checks | N4: 46142 | O4: Intro offer; outreach to local businesses; simple sign-up | P4: In Progress | R4: 0.9 | S4: Raja is on this iA
A5: =IF('Data (Master Table)'!$B5 = $K$1, 'Data (Master Table)'!C5, "") -> NO | B5: =IF('Data (Master Table)'!$B5 = $K$1, 'Data (Master Table)'!D5, "") -> Grow current Waqf capital by £60,000 by Sept 2026 | C5: =IF('Data (Master Table)'!$B5 = $K$1, 'Data (Master Table)'!E5, "") -> Perpetual income for AEC | D5: =IF('Data (Master Table)'!$B5 = $K$1, 'Data (Master Table)'!F5, "") -> Donation-dependent operations; limited reserves; no diversified income operational yet. Curently contains £75k | E5: =IF('Data (Master Table)'!$B5 = $K$1, 'Data (Master Table)'!G5, "") -> Finance | F5: =IF('Data (Master Table)'!$B5 = $K$1, 'Data (Master Table)'!H5, "") -> End of March End of June End of Sept | G5: =IF('Data (Master Table)'!$B5 = $K$1, 'Data (Master Table)'!I5, "") -> Raja / Kamraan | H5: =IF('Data (Master Table)'!$B5 = $K$1, 'Data (Master Table)'!J5, "") -> Low | ... J5: =IF('Data (Master Table)'!$B5 = $K$1, 'Data (Master Table)'!L5, "") -> 46203 | K5: Raise £60k additional funds for waqf investment | L5: 0 | M5: Ramadhan Waqf fundraising round 2 | N5: Last 10 days of Ramadhan | O5: Friday talks, create deck for last 10 days of Ramadhan | P5: In Progress | Q5: The amount we wanted to raise in the last 10 days of Ramadhan was not realised | S5: Will look to HNW network to achieve this
A6: =IF('Data (Master Table)'!$B6 = $K$1, 'Data (Master Table)'!C6, "") -> YES | B6: =IF('Data (Master Table)'!$B6 = $K$1, 'Data (Master Table)'!D6, "") -> Grow Waqf capital to £200,000 by Sept 2026 | C6: =IF('Data (Master Table)'!$B6 = $K$1, 'Data (Master Table)'!E6, "") -> Step-change in waqf investment amount | D6: =IF('Data (Master Table)'!$B6 = $K$1, 'Data (Master Table)'!F6, "") -> Donation-dependent operations; limited reserves; no diversified income operational yet. Curently contains £75k (+£60k Ramadhan iA) | E6: =IF('Data (Master Table)'!$B6 = $K$1, 'Data (Master Table)'!G6, "") -> Exec | F6: =IF('Data (Master Table)'!$B6 = $K$1, 'Data (Master Table)'!H6, "") -> End of March End of June End of Sept | G6: =IF('Data (Master Table)'!$B6 = $K$1, 'Data (Master Table)'!I6, "") -> Shaffiq | H6: =IF('Data (Master Table)'!$B6 = $K$1, 'Data (Master Table)'!J6, "") -> Medium | ... J6: =IF('Data (Master Table)'!$B6 = $K$1, 'Data (Master Table)'!L6, "") -> 46295 | K6: Increase waqf investment by further £65k | L6: 1 | M6: HNW and individual investor approach pack + roadshows | N6: 46266 | O6: Curated deck; Brunei / Malaysian network, donor lunches; targeted HNW outreach | P6: In Progress | R6: 0.7
A7: =IF('Data (Master Table)'!$B7 = $K$1, 'Data (Master Table)'!C7, "") -> YES | B7: =IF('Data (Master Table)'!$B7 = $K$1, 'Data (Master Table)'!D7, "") -> Achieve net-positive operating balance by Sept 2026 | C7: =IF('Data (Master Table)'!$B7 = $K$1, 'Data (Master Table)'!E7, "") -> Operational transparency + sustainability | D7: =IF('Data (Master Table)'!$B7 = $K$1, 'Data (Master Table)'!F7, "") -> Donation-dependent operations; limited reserves; no diversified income operational yet | E7: =IF('Data (Master Table)'!$B7 = $K$1, 'Data (Master Table)'!G7, "") -> Finance | F7: =IF('Data (Master Table)'!$B7 = $K$1, 'Data (Master Table)'!H7, "") -> End of March End of June End of Sept | G7: =IF('Data (Master Table)'!$B7 = $K$1, 'Data (Master Table)'!I7, "") -> Behzat / Raja / Kamraan | H7: =IF('Data (Master Table)'!$B7 = $K$1, 'Data (Master Table)'!J7, "") -> Low | ... J7: =IF('Data (Master Table)'!$B7 = $K$1, 'Data (Master Table)'!L7, "") -> 46295 | K7: Monthly finance dashboard & cost controls | L7: 1 | M7: Ramadhan BAU fundraising Dashboard creation | N7: 46266 | O7: Budget discipline; procurement policy | P7: In Progress | R7: 0
A8: =IF('Data (Master Table)'!$B8 = $K$1, 'Data (Master Table)'!C8, "") | B8: =IF('Data (Master Table)'!$B8 = $K$1, 'Data (Master Table)'!D8, "") | C8: =IF('Data (Master Table)'!$B8 = $K$1, 'Data (Master Table)'!E8, "") | D8: =IF('Data (Master Table)'!$B8 = $K$1, 'Data (Master Table)'!F8, "") | E8: =IF('Data (Master Table)'!$B8 = $K$1, 'Data (Master Table)'!G8, "") | F8: =IF('Data (Master Table)'!$B8 = $K$1, 'Data (Master Table)'!H8, "") | G8: =IF('Data (Master Table)'!$B8 = $K$1, 'Data (Master Table)'!I8, "") | H8: =IF('Data (Master Table)'!$B8 = $K$1, 'Data (Master Table)'!J8, "") | ... J8: =IF('Data (Master Table)'!$B8 = $K$1, 'Data (Master Table)'!L8, "")
A9: =IF('Data (Master Table)'!$B9 = $K$1, 'Data (Master Table)'!C9, "") | B9: =IF('Data (Master Table)'!$B9 = $K$1, 'Data (Master Table)'!D9, "") | C9: =IF('Data (Master Table)'!$B9 = $K$1, 'Data (Master Table)'!E9, "") | D9: =IF('Data (Master Table)'!$B9 = $K$1, 'Data (Master Table)'!F9, "") | E9: =IF('Data (Master Table)'!$B9 = $K$1, 'Data (Master Table)'!G9, "") | F9: =IF('Data (Master Table)'!$B9 = $K$1, 'Data (Master Table)'!H9, "") | G9: =IF('Data (Master Table)'!$B9 = $K$1, 'Data (Master Table)'!I9, "") | H9: =IF('Data (Master Table)'!$B9 = $K$1, 'Data (Master Table)'!J9, "") | ... J9: =IF('Data (Master Table)'!$B9 = $K$1, 'Data (Master Table)'!L9, "")
A10: =IF('Data (Master Table)'!$B10 = $K$1, 'Data (Master Table)'!C10, "") | B10: =IF('Data (Master Table)'!$B10 = $K$1, 'Data (Master Table)'!D10, "") | C10: =IF('Data (Master Table)'!$B10 = $K$1, 'Data (Master Table)'!E10, "") | D10: =IF('Data (Master Table)'!$B10 = $K$1, 'Data (Master Table)'!F10, "") | E10: =IF('Data (Master Table)'!$B10 = $K$1, 'Data (Master Table)'!G10, "") | F10: =IF('Data (Master Table)'!$B10 = $K$1, 'Data (Master Table)'!H10, "") | G10: =IF('Data (Master Table)'!$B10 = $K$1, 'Data (Master Table)'!I10, "") | H10: =IF('Data (Master Table)'!$B10 = $K$1, 'Data (Master Table)'!J10, "") | ... J10: =IF('Data (Master Table)'!$B10 = $K$1, 'Data (Master Table)'!L10, "")
A11: =IF('Data (Master Table)'!$B11 = $K$1, 'Data (Master Table)'!C11, "") | B11: =IF('Data (Master Table)'!$B11 = $K$1, 'Data (Master Table)'!D11, "") | C11: =IF('Data (Master Table)'!$B11 = $K$1, 'Data (Master Table)'!E11, "") | D11: =IF('Data (Master Table)'!$B11 = $K$1, 'Data (Master Table)'!F11, "") | E11: =IF('Data (Master Table)'!$B11 = $K$1, 'Data (Master Table)'!G11, "") | F11: =IF('Data (Master Table)'!$B11 = $K$1, 'Data (Master Table)'!H11, "") | G11: =IF('Data (Master Table)'!$B11 = $K$1, 'Data (Master Table)'!I11, "") | H11: =IF('Data (Master Table)'!$B11 = $K$1, 'Data (Master Table)'!J11, "") | ... J11: =IF('Data (Master Table)'!$B11 = $K$1, 'Data (Master Table)'!L11, "")
A12: =IF('Data (Master Table)'!$B12 = $K$1, 'Data (Master Table)'!C12, "") | B12: =IF('Data (Master Table)'!$B12 = $K$1, 'Data (Master Table)'!D12, "") | C12: =IF('Data (Master Table)'!$B12 = $K$1, 'Data (Master Table)'!E12, "") | D12: =IF('Data (Master Table)'!$B12 = $K$1, 'Data (Master Table)'!F12, "") | E12: =IF('Data (Master Table)'!$B12 = $K$1, 'Data (Master Table)'!G12, "") | F12: =IF('Data (Master Table)'!$B12 = $K$1, 'Data (Master Table)'!H12, "") | G12: =IF('Data (Master Table)'!$B12 = $K$1, 'Data (Master Table)'!I12, "") | H12: =IF('Data (Master Table)'!$B12 = $K$1, 'Data (Master Table)'!J12, "") | ... J12: =IF('Data (Master Table)'!$B12 = $K$1, 'Data (Master Table)'!L12, "")
A13: =IF('Data (Master Table)'!$B13 = $K$1, 'Data (Master Table)'!C13, "") | B13: =IF('Data (Master Table)'!$B13 = $K$1, 'Data (Master Table)'!D13, "") | C13: =IF('Data (Master Table)'!$B13 = $K$1, 'Data (Master Table)'!E13, "") | D13: =IF('Data (Master Table)'!$B13 = $K$1, 'Data (Master Table)'!F13, "") | E13: =IF('Data (Master Table)'!$B13 = $K$1, 'Data (Master Table)'!G13, "") | F13: =IF('Data (Master Table)'!$B13 = $K$1, 'Data (Master Table)'!H13, "") | G13: =IF('Data (Master Table)'!$B13 = $K$1, 'Data (Master Table)'!I13, "") | H13: =IF('Data (Master Table)'!$B13 = $K$1, 'Data (Master Table)'!J13, "") | ... J13: =IF('Data (Master Table)'!$B13 = $K$1, 'Data (Master Table)'!L13, "")
A14: =IF('Data (Master Table)'!$B14 = $K$1, 'Data (Master Table)'!C14, "") | B14: =IF('Data (Master Table)'!$B14 = $K$1, 'Data (Master Table)'!D14, "") | C14: =IF('Data (Master Table)'!$B14 = $K$1, 'Data (Master Table)'!E14, "") | D14: =IF('Data (Master Table)'!$B14 = $K$1, 'Data (Master Table)'!F14, "") | E14: =IF('Data (Master Table)'!$B14 = $K$1, 'Data (Master Table)'!G14, "") | F14: =IF('Data (Master Table)'!$B14 = $K$1, 'Data (Master Table)'!H14, "") | G14: =IF('Data (Master Table)'!$B14 = $K$1, 'Data (Master Table)'!I14, "") | H14: =IF('Data (Master Table)'!$B14 = $K$1, 'Data (Master Table)'!J14, "") | ... J14: =IF('Data (Master Table)'!$B14 = $K$1, 'Data (Master Table)'!L14, "")
A15: =IF('Data (Master Table)'!$B15 = $K$1, 'Data (Master Table)'!C15, "") | B15: =IF('Data (Master Table)'!$B15 = $K$1, 'Data (Master Table)'!D15, "") | C15: =IF('Data (Master Table)'!$B15 = $K$1, 'Data (Master Table)'!E15, "") | D15: =IF('Data (Master Table)'!$B15 = $K$1, 'Data (Master Table)'!F15, "") | E15: =IF('Data (Master Table)'!$B15 = $K$1, 'Data (Master Table)'!G15, "") | F15: =IF('Data (Master Table)'!$B15 = $K$1, 'Data (Master Table)'!H15, "") | G15: =IF('Data (Master Table)'!$B15 = $K$1, 'Data (Master Table)'!I15, "") | H15: =IF('Data (Master Table)'!$B15 = $K$1, 'Data (Master Table)'!J15, "") | ... J15: =IF('Data (Master Table)'!$B15 = $K$1, 'Data (Master Table)'!L15, "")
A16: =IF('Data (Master Table)'!$B16 = $K$1, 'Data (Master Table)'!C16, "") | B16: =IF('Data (Master Table)'!$B16 = $K$1, 'Data (Master Table)'!D16, "") | C16: =IF('Data (Master Table)'!$B16 = $K$1, 'Data (Master Table)'!E16, "") | D16: =IF('Data (Master Table)'!$B16 = $K$1, 'Data (Master Table)'!F16, "") | E16: =IF('Data (Master Table)'!$B16 = $K$1, 'Data (Master Table)'!G16, "") | F16: =IF('Data (Master Table)'!$B16 = $K$1, 'Data (Master Table)'!H16, "") | G16: =IF('Data (Master Table)'!$B16 = $K$1, 'Data (Master Table)'!I16, "") | H16: =IF('Data (Master Table)'!$B16 = $K$1, 'Data (Master Table)'!J16, "") | ... J16: =IF('Data (Master Table)'!$B16 = $K$1, 'Data (Master Table)'!L16, "")

Sheet Youth Succession Planning
A1: ULTIMATE AIM : DEVELOP YOUTH LEADERSHIP + SUCCESSION PLANNING SLT Lead Avais | K1: ='Data (Master Table)'!W4 -> Youth Succession Planning
A2: ='Data (Master Table)'!C2 -> IS VALID | B2: ='Data (Master Table)'!D2 -> SMART Outcome | C2: ='Data (Master Table)'!E2 -> Benefit | D2: ='Data (Master Table)'!F2 -> Starting Point / Baseline | E2: ='Data (Master Table)'!G2 -> Department | F2: ='Data (Master Table)'!H2 -> Reported to OPEX | G2: ='Data (Master Table)'!I2 -> Responsible Person | H2: ='Data (Master Table)'!J2 -> Risk Level | ... S2: ='Data (Master Table)'!U2 -> Notes
A3: =IF('Data (Master Table)'!$B18 = $K$1, 'Data (Master Table)'!C18, "") -> YES | B3: =IF('Data (Master Table)'!$B18 = $K$1, 'Data (Master Table)'!D18, "") -> Develop youth leadership | C3: =IF('Data (Master Table)'!$B18 = $K$1, 'Data (Master Table)'!E18, "") -> Pipeline of young leaders, succession planning | D3: =IF('Data (Master Table)'!$B18 = $K$1, 'Data (Master Table)'!F18, "") -> No formal youth leadership structure; involvement is ad‑hoc and reactive | E3: =IF('Data (Master Table)'!$B18 = $K$1, 'Data (Master Table)'!G18, "") -> Youth | F3: =IF('Data (Master Table)'!$B18 = $K$1, 'Data (Master Table)'!H18, "") -> End of March End of June End of Sept | G3: =IF('Data (Master Table)'!$B18 = $K$1, 'Data (Master Table)'!I18, "") -> Afsor | H3: =IF('Data (Master Table)'!$B18 = $K$1, 'Data (Master Table)'!J18, "") -> Medium | ... J3: =IF('Data (Master Table)'!$B18 = $K$1, 'Data (Master Table)'!L18, "") -> 46068 | K3: Establish Youth Council (10 members) + Shadow Trustees + Key staff positions proteges allocated | L3: 1 | M3: Clear roles; mentor pairing; monthly meetings, Liaise with Madrassa, Scouts, Boxing and Taekwondo functions | N3: Target end Ramadan for first results | O3: Ramadan: Volunteer Request, Omar Youth talks > key to identify youth. Youth Experience event plan for post Ramadan. | P3: In Progress | R3: 0.8 | S3: Results Ramadan> Youth activiites - building responsibility for the youth across the mosque. Demonstrated across youth events, running the coffee cart (i.e not just running, but also increasing product range to generate more "revenue" for the mosque), youth volunteers. How does this line with pipelne of young leaders: We have identified young leaders who we would recommend as part of a youth leadership strucutre that can support our growth. So based on we have identnfied caditates and now its about setting the strucutre, we have completed 40%, next 20% is setting structure, next 20% is executing it, and final 20% is ensuring its operating as part of the wider management teams. Q2: setting up youth board in progress.
A4: =IF('Data (Master Table)'!$B19 = $K$1, 'Data (Master Table)'!C19, "") -> YES | B4: =IF('Data (Master Table)'!$B19 = $K$1, 'Data (Master Table)'!D19, "") -> Increase youth volunteering team by 40% | C4: =IF('Data (Master Table)'!$B19 = $K$1, 'Data (Master Table)'!E19, "") -> Higher engagement & continuity | D4: =IF('Data (Master Table)'!$B19 = $K$1, 'Data (Master Table)'!F19, "") -> Current team number: X | E4: =IF('Data (Master Table)'!$B19 = $K$1, 'Data (Master Table)'!G19, "") -> Youth | F4: =IF('Data (Master Table)'!$B19 = $K$1, 'Data (Master Table)'!H19, "") -> End of March End of June End of Sept | G4: =IF('Data (Master Table)'!$B19 = $K$1, 'Data (Master Table)'!I19, "") -> Afsor | H4: =IF('Data (Master Table)'!$B19 = $K$1, 'Data (Master Table)'!J19, "") -> Low | ... J4: =IF('Data (Master Table)'!$B19 = $K$1, 'Data (Master Table)'!L19, "") -> 46203 | K4: Quarterly youth volunteer drives | L4: 1 | M4: School/college outreach; buddy system | N4: Target end Ramadan for first results | O4: Ramadan - youth voltuneering kicked off. | P4: In Progress | R4: 0.6 | S4: Q1:Results Ramadan: Youth volunteering from our advertising was not as successful but we had youth volunteering more by supporting the young adults i.e. Davids kids were helping coffee stand. We just need a bit more forward planning around youth volunteer requirements leading up to events, lead with young adults .. this will yield better results in future. Q2: We are building a core set of youth who are very engaged. Summer will be an important time to build events which bring our youth together.
A5: =IF('Data (Master Table)'!$B20 = $K$1, 'Data (Master Table)'!C20, "") -> YES | B5: =IF('Data (Master Table)'!$B20 = $K$1, 'Data (Master Table)'!D20, "") -> Targeted talks to attract youth | C5: =IF('Data (Master Table)'!$B20 = $K$1, 'Data (Master Table)'!E20, "") -> Higher engagement & building youth connection to masjid | D5: =IF('Data (Master Table)'!$B20 = $K$1, 'Data (Master Table)'!F20, "") -> Ad-hoc talks currently | E5: =IF('Data (Master Table)'!$B20 = $K$1, 'Data (Master Table)'!G20, "") -> Youth | F5: =IF('Data (Master Table)'!$B20 = $K$1, 'Data (Master Table)'!H20, "") -> End of March End of June End of Sept | G5: =IF('Data (Master Table)'!$B20 = $K$1, 'Data (Master Table)'!I20, "") -> Afsor | H5: =IF('Data (Master Table)'!$B20 = $K$1, 'Data (Master Table)'!J20, "") -> Medium | ... J5: =IF('Data (Master Table)'!$B20 = $K$1, 'Data (Master Table)'!L20, "") -> 46112 | K5: Plan and deliver targeted talks for all youth demographics | L5: 6 | M5: 1 every 2 months | N5: Target end Ramadan for first results | O5: Working with Omar to create a better set of talks for youth. Focus is not purley on topic, but more on connecting them to mentors + people they can respect/look up too (people who are not to old). First test of this will be in Ramadan. | P5: In Progress | R5: 0.6 | S5: Ramadan Resulst > Continue youth. Omar and Eni doing a great job. Think we need a sisters lead one switch at some point. 60% completion rate once we get consisten cy, have new people joining, 80% once we see engagement from youth outsend youth talks and final 100% swhen we have sister led sessions as well
A6: =IF('Data (Master Table)'!$B21 = $K$1, 'Data (Master Table)'!C21, "") -> YES | B6: =IF('Data (Master Table)'!$B21 = $K$1, 'Data (Master Table)'!D21, "") -> Bi-monthly events to attract youth | C6: =IF('Data (Master Table)'!$B21 = $K$1, 'Data (Master Table)'!E21, "") -> Higher engagement & building youth connection to masjid | D6: =IF('Data (Master Table)'!$B21 = $K$1, 'Data (Master Table)'!F21, "") -> Ad-hoc events running currently | E6: =IF('Data (Master Table)'!$B21 = $K$1, 'Data (Master Table)'!G21, "") -> Youth | F6: =IF('Data (Master Table)'!$B21 = $K$1, 'Data (Master Table)'!H21, "") -> End of March End of June End of Sept | G6: =IF('Data (Master Table)'!$B21 = $K$1, 'Data (Master Table)'!I21, "") -> Afsor | H6: =IF('Data (Master Table)'!$B21 = $K$1, 'Data (Master Table)'!J21, "") -> High | ... J6: =IF('Data (Master Table)'!$B21 = $K$1, 'Data (Master Table)'!L21, "") -> 46112 | K6: Plan and deliver fortnightly events, social, Islamic, food etc for specific youth demographics | L6: 24 | M6: 2 every month | N6: on-going | O6: While this is aspiration. For youth, possible. We will continue with consistency on boys and girls circles. For the YA, we want to build more on providing experiences e.g. hike at seven sisters etc. Build stronger bonds + friendships. This helps them feel more connected to the mosque and the community. | P6: In Progress | R6: 0.5 | S6: Q1: Ideas being progress: Experienced based events. Volunteering. DoE - our first volunteer. Building plans. Q2: Summer will be key. Where we want to get more volunteers and more experiences for youth.
A7: =IF('Data (Master Table)'!$B22 = $K$1, 'Data (Master Table)'!C22, "") -> YES | B7: =IF('Data (Master Table)'!$B22 = $K$1, 'Data (Master Table)'!D22, "") -> Leadership development | C7: =IF('Data (Master Table)'!$B22 = $K$1, 'Data (Master Table)'!E22, "") -> Safer, more competent teams | D7: =IF('Data (Master Table)'!$B22 = $K$1, 'Data (Master Table)'!F22, "") -> No formal youth leadership structure; involvement is ad‑hoc and reactive | E7: =IF('Data (Master Table)'!$B22 = $K$1, 'Data (Master Table)'!G22, "") -> OPEX | F7: =IF('Data (Master Table)'!$B22 = $K$1, 'Data (Master Table)'!H22, "") -> End of March End of June End of Sept | G7: =IF('Data (Master Table)'!$B22 = $K$1, 'Data (Master Table)'!I22, "") -> Amer | H7: =IF('Data (Master Table)'!$B22 = $K$1, 'Data (Master Table)'!J22, "") -> Low | ... J7: =IF('Data (Master Table)'!$B22 = $K$1, 'Data (Master Table)'!L22, "") -> 46112 | K7: Training calendar (safeguarding, first aid, comms) | L7: 1 | M7: Book trainers; certificates; track completion | N7: 18.01.26 | O7: Begin leadership development programme with Yusra training | P7: In Progress | Q7: Completion of pre-training 1-2-1 sessions with OPEX | R7: 0.7 | S7: Youth Lead Afsor Miah is captured within this training programme. Following MOSCARS awards ceremony several youth volunteers were identified for consideration for a youth council or shadow trustee/directors board. Shaffiq has put document tyogether detailing proposed structure. Some of the youth m,embers have also attended Yusar training sessions.
A8: =IF('Data (Master Table)'!$B23 = $K$1, 'Data (Master Table)'!C23, "") -> YES | B8: =IF('Data (Master Table)'!$B23 = $K$1, 'Data (Master Table)'!D23, "") -> Leadership development | C8: =IF('Data (Master Table)'!$B23 = $K$1, 'Data (Master Table)'!E23, "") -> Pipeline of young leaders, succession planning | D8: =IF('Data (Master Table)'!$B23 = $K$1, 'Data (Master Table)'!F23, "") -> Scouts provision low | E8: =IF('Data (Master Table)'!$B23 = $K$1, 'Data (Master Table)'!G23, "") -> Scouts | F8: =IF('Data (Master Table)'!$B23 = $K$1, 'Data (Master Table)'!H23, "") -> End of March End of June End of Sept | G8: =IF('Data (Master Table)'!$B23 = $K$1, 'Data (Master Table)'!I23, "") -> Khaleeq | H8: =IF('Data (Master Table)'!$B23 = $K$1, 'Data (Master Table)'!J23, "") -> Medium | ... J8: =IF('Data (Master Table)'!$B23 = $K$1, 'Data (Master Table)'!L23, "") -> 46112 | K8: Increase number of Scouts places- key issue; staffing | L8: 1 | M8: Increase staff numbers | N8: 31.01.26 | O8: Advertising targeted for Q1. Story around impact and outcomes. We will keep on top of this. We will review impact. | P8: Not Started | R8: 0 | S8: Risk: Scout leader is leaving. Need to first onboard a new lead Lack of volunteers are we progressing this?
A9: =IF('Data (Master Table)'!$B24 = $K$1, 'Data (Master Table)'!C24, "") | B9: =IF('Data (Master Table)'!$B24 = $K$1, 'Data (Master Table)'!D24, "") | C9: =IF('Data (Master Table)'!$B24 = $K$1, 'Data (Master Table)'!E24, "") | D9: =IF('Data (Master Table)'!$B24 = $K$1, 'Data (Master Table)'!F24, "") | E9: =IF('Data (Master Table)'!$B24 = $K$1, 'Data (Master Table)'!G24, "") | F9: =IF('Data (Master Table)'!$B24 = $K$1, 'Data (Master Table)'!H24, "") | G9: =IF('Data (Master Table)'!$B24 = $K$1, 'Data (Master Table)'!I24, "") | H9: =IF('Data (Master Table)'!$B24 = $K$1, 'Data (Master Table)'!J24, "") | ... J9: =IF('Data (Master Table)'!$B24 = $K$1, 'Data (Master Table)'!L24, "")
A10: =IF('Data (Master Table)'!$B25 = $K$1, 'Data (Master Table)'!C25, "") | B10: =IF('Data (Master Table)'!$B25 = $K$1, 'Data (Master Table)'!D25, "") | C10: =IF('Data (Master Table)'!$B25 = $K$1, 'Data (Master Table)'!E25, "") | D10: =IF('Data (Master Table)'!$B25 = $K$1, 'Data (Master Table)'!F25, "") | E10: =IF('Data (Master Table)'!$B25 = $K$1, 'Data (Master Table)'!G25, "") | F10: =IF('Data (Master Table)'!$B25 = $K$1, 'Data (Master Table)'!H25, "") | G10: =IF('Data (Master Table)'!$B25 = $K$1, 'Data (Master Table)'!I25, "") | H10: =IF('Data (Master Table)'!$B25 = $K$1, 'Data (Master Table)'!J25, "") | ... J10: =IF('Data (Master Table)'!$B25 = $K$1, 'Data (Master Table)'!L25, "")
A11: =IF('Data (Master Table)'!$B26 = $K$1, 'Data (Master Table)'!C26, "") | B11: =IF('Data (Master Table)'!$B26 = $K$1, 'Data (Master Table)'!D26, "") | C11: =IF('Data (Master Table)'!$B26 = $K$1, 'Data (Master Table)'!E26, "") | D11: =IF('Data (Master Table)'!$B26 = $K$1, 'Data (Master Table)'!F26, "") | E11: =IF('Data (Master Table)'!$B26 = $K$1, 'Data (Master Table)'!G26, "") | F11: =IF('Data (Master Table)'!$B26 = $K$1, 'Data (Master Table)'!H26, "") | G11: =IF('Data (Master Table)'!$B26 = $K$1, 'Data (Master Table)'!I26, "") | H11: =IF('Data (Master Table)'!$B26 = $K$1, 'Data (Master Table)'!J26, "") | ... J11: =IF('Data (Master Table)'!$B26 = $K$1, 'Data (Master Table)'!L26, "")
A12: =IF('Data (Master Table)'!$B27 = $K$1, 'Data (Master Table)'!C27, "") | B12: =IF('Data (Master Table)'!$B27 = $K$1, 'Data (Master Table)'!D27, "") | C12: =IF('Data (Master Table)'!$B27 = $K$1, 'Data (Master Table)'!E27, "") | D12: =IF('Data (Master Table)'!$B27 = $K$1, 'Data (Master Table)'!F27, "") | E12: =IF('Data (Master Table)'!$B27 = $K$1, 'Data (Master Table)'!G27, "") | F12: =IF('Data (Master Table)'!$B27 = $K$1, 'Data (Master Table)'!H27, "") | G12: =IF('Data (Master Table)'!$B27 = $K$1, 'Data (Master Table)'!I27, "") | H12: =IF('Data (Master Table)'!$B27 = $K$1, 'Data (Master Table)'!J27, "") | ... J12: =IF('Data (Master Table)'!$B27 = $K$1, 'Data (Master Table)'!L27, "")
A13: =IF('Data (Master Table)'!$B28 = $K$1, 'Data (Master Table)'!C28, "") | B13: =IF('Data (Master Table)'!$B28 = $K$1, 'Data (Master Table)'!D28, "") | C13: =IF('Data (Master Table)'!$B28 = $K$1, 'Data (Master Table)'!E28, "") | D13: =IF('Data (Master Table)'!$B28 = $K$1, 'Data (Master Table)'!F28, "") | E13: =IF('Data (Master Table)'!$B28 = $K$1, 'Data (Master Table)'!G28, "") | F13: =IF('Data (Master Table)'!$B28 = $K$1, 'Data (Master Table)'!H28, "") | G13: =IF('Data (Master Table)'!$B28 = $K$1, 'Data (Master Table)'!I28, "") | H13: =IF('Data (Master Table)'!$B28 = $K$1, 'Data (Master Table)'!J28, "") | ... J13: =IF('Data (Master Table)'!$B28 = $K$1, 'Data (Master Table)'!L28, "")
A14: =IF('Data (Master Table)'!$B29 = $K$1, 'Data (Master Table)'!C29, "") | B14: =IF('Data (Master Table)'!$B29 = $K$1, 'Data (Master Table)'!D29, "") | C14: =IF('Data (Master Table)'!$B29 = $K$1, 'Data (Master Table)'!E29, "") | D14: =IF('Data (Master Table)'!$B29 = $K$1, 'Data (Master Table)'!F29, "") | E14: =IF('Data (Master Table)'!$B29 = $K$1, 'Data (Master Table)'!G29, "") | F14: =IF('Data (Master Table)'!$B29 = $K$1, 'Data (Master Table)'!H29, "") | G14: =IF('Data (Master Table)'!$B29 = $K$1, 'Data (Master Table)'!I29, "") | H14: =IF('Data (Master Table)'!$B29 = $K$1, 'Data (Master Table)'!J29, "") | ... J14: =IF('Data (Master Table)'!$B29 = $K$1, 'Data (Master Table)'!L29, "")
A15: =IF('Data (Master Table)'!$B30 = $K$1, 'Data (Master Table)'!C30, "") | B15: =IF('Data (Master Table)'!$B30 = $K$1, 'Data (Master Table)'!D30, "") | C15: =IF('Data (Master Table)'!$B30 = $K$1, 'Data (Master Table)'!E30, "") | D15: =IF('Data (Master Table)'!$B30 = $K$1, 'Data (Master Table)'!F30, "") | E15: =IF('Data (Master Table)'!$B30 = $K$1, 'Data (Master Table)'!G30, "") | F15: =IF('Data (Master Table)'!$B30 = $K$1, 'Data (Master Table)'!H30, "") | G15: =IF('Data (Master Table)'!$B30 = $K$1, 'Data (Master Table)'!I30, "") | H15: =IF('Data (Master Table)'!$B30 = $K$1, 'Data (Master Table)'!J30, "") | ... J15: =IF('Data (Master Table)'!$B30 = $K$1, 'Data (Master Table)'!L30, "")
A16: =IF('Data (Master Table)'!$B31 = $K$1, 'Data (Master Table)'!C31, "") | B16: =IF('Data (Master Table)'!$B31 = $K$1, 'Data (Master Table)'!D31, "") | C16: =IF('Data (Master Table)'!$B31 = $K$1, 'Data (Master Table)'!E31, "") | D16: =IF('Data (Master Table)'!$B31 = $K$1, 'Data (Master Table)'!F31, "") | E16: =IF('Data (Master Table)'!$B31 = $K$1, 'Data (Master Table)'!G31, "") | F16: =IF('Data (Master Table)'!$B31 = $K$1, 'Data (Master Table)'!H31, "") | G16: =IF('Data (Master Table)'!$B31 = $K$1, 'Data (Master Table)'!I31, "") | H16: =IF('Data (Master Table)'!$B31 = $K$1, 'Data (Master Table)'!J31, "") | ... J16: =IF('Data (Master Table)'!$B31 = $K$1, 'Data (Master Table)'!L31, "")

Sheet Wider Community Engagement
A1: ULTIMATE AIM : BUILD BENEFICIAL PARTNERSHIPS SLT - Lead Matiur | K1: ='Data (Master Table)'!W5 -> Wider Community Engagement
A2: ='Data (Master Table)'!C2 -> IS VALID | B2: ='Data (Master Table)'!D2 -> SMART Outcome | C2: ='Data (Master Table)'!E2 -> Benefit | D2: ='Data (Master Table)'!F2 -> Starting Point / Baseline | E2: ='Data (Master Table)'!G2 -> Department | F2: ='Data (Master Table)'!H2 -> Reported to OPEX | G2: ='Data (Master Table)'!I2 -> Responsible Person | H2: ='Data (Master Table)'!J2 -> Risk Level | ... S2: ='Data (Master Table)'!U2 -> Notes
A3: =IF('Data (Master Table)'!$B33 = $K$1, 'Data (Master Table)'!C33, "") -> YES | B3: =IF('Data (Master Table)'!$B33 = $K$1, 'Data (Master Table)'!D33, "") -> Build partnerships | C3: =IF('Data (Master Table)'!$B33 = $K$1, 'Data (Master Table)'!E33, "") -> Shared impact & credibility, improved societal integration | D3: =IF('Data (Master Table)'!$B33 = $K$1, 'Data (Master Table)'!F33, "") -> 3–4 informal partnerships; sporadic open days; no structured annual calendar | E3: =IF('Data (Master Table)'!$B33 = $K$1, 'Data (Master Table)'!G33, "") -> Community / Politics | F3: =IF('Data (Master Table)'!$B33 = $K$1, 'Data (Master Table)'!H33, "") -> End of March End of June End of Sept | G3: =IF('Data (Master Table)'!$B33 = $K$1, 'Data (Master Table)'!I33, "") -> Matiur | H3: =IF('Data (Master Table)'!$B33 = $K$1, 'Data (Master Table)'!J33, "") -> Medium | ... J3: =IF('Data (Master Table)'!$B33 = $K$1, 'Data (Master Table)'!L33, "") -> 46173 | K3: Sign 5 MOUs with local orgs | L3: 3 | M3: 1. Target list (schools, council, charities); template MOU 2. Set up Bromley Citizens UK 3. Recruit more volunteers for Citizens UK | N3: 1. Apr 2. Sept 3. Feb | O3: Further Citizen's UK meeting attended by other community members | P3: In Progress | R3: 0.4 | S3: Founding Assembly of Bromley Citizens to be held on 30th April
A4: =IF('Data (Master Table)'!$B34 = $K$1, 'Data (Master Table)'!C34, "") -> YES | B4: =IF('Data (Master Table)'!$B34 = $K$1, 'Data (Master Table)'!D34, "") -> Community events | C4: =IF('Data (Master Table)'!$B34 = $K$1, 'Data (Master Table)'!E34, "") -> Improved public perception and relationships, increased local impact | D4: =IF('Data (Master Table)'!$B34 = $K$1, 'Data (Master Table)'!F34, "") -> 3–4 informal partnerships; sporadic open days; no structured annual calendar | E4: =IF('Data (Master Table)'!$B34 = $K$1, 'Data (Master Table)'!G34, "") -> Community / Politics | F4: =IF('Data (Master Table)'!$B34 = $K$1, 'Data (Master Table)'!H34, "") -> End of March End of June End of Sept | G4: =IF('Data (Master Table)'!$B34 = $K$1, 'Data (Master Table)'!I34, "") -> Avais | H4: =IF('Data (Master Table)'!$B34 = $K$1, 'Data (Master Table)'!J34, "") -> Medium | ... J4: =IF('Data (Master Table)'!$B34 = $K$1, 'Data (Master Table)'!L34, "") -> 46295 | K4: Deliver 4 open community events | L4: 5 | M4: Plan calendar; steward training; inclusive themes. Include neighbourhood consultation (first build relationships, then ask what are your needs?)and Interfaith iftar | N4: Feb - Calendar May - Eid Jun - World Cup Sep - Dec - Christmas | O4: Online community Calendar is ready for Ramadan! Build an informal way of engaging with the mosque space to make it more accessiable for non muslims. Event invitations to consider non-muslim community. Partnerships - tbc | P4: In Progress | R4: 0.5 | S4: Calendar up and running. Testing during Ramdan. Avais and Meryem to own, keep up to date. Need to make this calendar more avalaible to non muslim community. Coffee Cart super successful, we need to get someone to own this and also this need sto beome a more regular daily service. Q2: Progressing well. Eid event we invited wider community. I am keen to do an Art event, farmers market in August etc
A5: =IF('Data (Master Table)'!$B35 = $K$1, 'Data (Master Table)'!C35, "") -> YES | B5: =IF('Data (Master Table)'!$B35 = $K$1, 'Data (Master Table)'!D35, "") -> Transparency | C5: =IF('Data (Master Table)'!$B35 = $K$1, 'Data (Master Table)'!E35, "") -> Evidence for funders & partners | D5: =IF('Data (Master Table)'!$B35 = $K$1, 'Data (Master Table)'!F35, "") -> 3–4 informal partnerships; sporadic open days; no structured annual calendar | E5: =IF('Data (Master Table)'!$B35 = $K$1, 'Data (Master Table)'!G35, "") -> Community / Politics | F5: =IF('Data (Master Table)'!$B35 = $K$1, 'Data (Master Table)'!H35, "") -> End of March End of June End of Sept | G5: =IF('Data (Master Table)'!$B35 = $K$1, 'Data (Master Table)'!I35, "") -> Avais | H5: =IF('Data (Master Table)'!$B35 = $K$1, 'Data (Master Table)'!J35, "") -> Low | ... J5: =IF('Data (Master Table)'!$B35 = $K$1, 'Data (Master Table)'!L35, "") -> 46295 | K5: Publish annual Community Impact Report | L5: 3 | M5: Collect metrics; case studies; design & print | N5: On-going | O5: Ensuring data capturing of events is requested before events. Looking to get more youth to take videos/photos during evets | P5: Complete | R5: 1 | S5: We are getting data for events every time which is good, succewss is shared throguh leads utd, and we are keeping each other updated. Good progress on this and its linked well to marketing
A6: =IF('Data (Master Table)'!$B36 = $K$1, 'Data (Master Table)'!C36, "") -> YES | B6: =IF('Data (Master Table)'!$B36 = $K$1, 'Data (Master Table)'!D36, "") -> Non-Muslims understand Islam | C6: =IF('Data (Master Table)'!$B36 = $K$1, 'Data (Master Table)'!E36, "") -> Spreading the Deen and benefitting local community. Islamic stereotypes broken | D6: =IF('Data (Master Table)'!$B36 = $K$1, 'Data (Master Table)'!F36, "") -> Recruited da'ee group; completing training. Dawah stall equipment and clothing being sourced, branding complete. Awaiting stall permission from Bromley Council | E6: =IF('Data (Master Table)'!$B36 = $K$1, 'Data (Master Table)'!G36, "") -> Religious Affairs | F6: =IF('Data (Master Table)'!$B36 = $K$1, 'Data (Master Table)'!H36, "") -> End of March End of June End of Sept | G6: =IF('Data (Master Table)'!$B36 = $K$1, 'Data (Master Table)'!I36, "") -> Ahmed | H6: =IF('Data (Master Table)'!$B36 = $K$1, 'Data (Master Table)'!J36, "") -> Low | ... J6: =IF('Data (Master Table)'!$B36 = $K$1, 'Data (Master Table)'!L36, "") -> 46053 | K6: Live, active Da'wah project | L6: 3 | M6: 1. Complete purchases of equipment 2. Stall permission granted 3. Volunteer training complete | N6: 1. Jan end 2. Jan end 3. Jan end | P6: In Progress | R6: 0.9
A7: =IF('Data (Master Table)'!$B37 = $K$1, 'Data (Master Table)'!C37, "") -> YES | B7: =IF('Data (Master Table)'!$B37 = $K$1, 'Data (Master Table)'!D37, "") -> Engage and connect with local schools and scouts groups | C7: =IF('Data (Master Table)'!$B37 = $K$1, 'Data (Master Table)'!E37, "") -> Active daw'ah and increasing Islamic knowledge (including breaking stereotypes) of young local people through immersive experiences | D7: =IF('Data (Master Table)'!$B37 = $K$1, 'Data (Master Table)'!F37, "") -> School and scouts visits service already active, through school/scout group contact | E7: =IF('Data (Master Table)'!$B37 = $K$1, 'Data (Master Table)'!G37, "") -> Education | F7: =IF('Data (Master Table)'!$B37 = $K$1, 'Data (Master Table)'!H37, "") -> End of March End of June End of Sept | G7: =IF('Data (Master Table)'!$B37 = $K$1, 'Data (Master Table)'!I37, "") -> Sobia | H7: =IF('Data (Master Table)'!$B37 = $K$1, 'Data (Master Table)'!J37, "") -> Low | ... J7: =IF('Data (Master Table)'!$B37 = $K$1, 'Data (Master Table)'!L37, "") -> 46173 | K7: Service to become proactive, reaching out to schools /scout groups | L7: 6 | M7: 1. Attract and retain further volunteers 2. Begin actively reaching out to schools/scout groups 3. Engage Bromley College 4. Invite them to our wider events 5. Get them to partake in our Ramadhan Challenge and iftars | N7: 1. Jan Mid 2. May End 3. Feb End 4. Feb Begin 5. Feb end | O7: Successfully attracted and retained additional volunteers to support the mosque visits programme. | P7: In Progress | R7: 0.5
A8: =IF('Data (Master Table)'!$B38 = $K$1, 'Data (Master Table)'!C38, "") -> YES | B8: =IF('Data (Master Table)'!$B38 = $K$1, 'Data (Master Table)'!D38, "") -> Deepen relationships and benefit from connections to other faiths | C8: =IF('Data (Master Table)'!$B38 = $K$1, 'Data (Master Table)'!E38, "") -> Learn from them, teach them about Islam, break stereotypes, aid geo/political dialogues/situations | D8: =IF('Data (Master Table)'!$B38 = $K$1, 'Data (Master Table)'!F38, "") -> Already esablished long term Interfaith relationships | E8: =IF('Data (Master Table)'!$B38 = $K$1, 'Data (Master Table)'!G38, "") -> Education | F8: =IF('Data (Master Table)'!$B38 = $K$1, 'Data (Master Table)'!H38, "") -> End of March End of June End of Sept | G8: =IF('Data (Master Table)'!$B38 = $K$1, 'Data (Master Table)'!I38, "") -> Sofi | H8: =IF('Data (Master Table)'!$B38 = $K$1, 'Data (Master Table)'!J38, "") -> Medium | ... J8: =IF('Data (Master Table)'!$B38 = $K$1, 'Data (Master Table)'!L38, "") -> 46280 | K8: Participate in regular Interfaith meetings and continue to educate about Islam, lessons learned from our shared prophets and highlight the advantages of being a people of peace who pray, fast and are ready to help others | L8: 3 | M8: 1. Get more of our community involved 2. Strengthen relationships with focus on Justice 3. Benefit from learning about how other faiths function,e.g. financial set up of Christians, power dynamics from Jews. 4.Plan Islamophobia and anti-semitism workshops | N8: 1. Feb end 2. Apr end 3. Sep end | O8: 1. Work in progress re drawing more of our community . Issues are due to advertising events late, this is partly due to the sensitive nature of the topics and have been hesitant to advertise. 2 | P8: In Progress | R8: 0.5
A9: =IF('Data (Master Table)'!$B39 = $K$1, 'Data (Master Table)'!C39, "") -> YES | B9: =IF('Data (Master Table)'!$B39 = $K$1, 'Data (Master Table)'!D39, "") -> Connect with, market, and advertise well with wider community | C9: =IF('Data (Master Table)'!$B39 = $K$1, 'Data (Master Table)'!E39, "") -> Improved community cohesion | D9: =IF('Data (Master Table)'!$B39 = $K$1, 'Data (Master Table)'!F39, "") -> Have an existing but out of date and non searchable database. A sharepoint version now exists in SharePoint | E9: =IF('Data (Master Table)'!$B39 = $K$1, 'Data (Master Table)'!G39, "") -> Community / Politics | F9: =IF('Data (Master Table)'!$B39 = $K$1, 'Data (Master Table)'!H39, "") -> End of March End of June End of Sept | G9: =IF('Data (Master Table)'!$B39 = $K$1, 'Data (Master Table)'!I39, "") -> Matiur | H9: =IF('Data (Master Table)'!$B39 = $K$1, 'Data (Master Table)'!J39, "") -> Medium | ... J9: =IF('Data (Master Table)'!$B39 = $K$1, 'Data (Master Table)'!L39, "") -> 46234 | K9: Build useful, searchable, regularly updated database of community contacts | L9: 1 | P9: In Progress | R9: 0.1 | S9: To be reviewed after Eid. Interfaith iftar invitations was not well executed with many key stakeholders missed
A10: =IF('Data (Master Table)'!$B40 = $K$1, 'Data (Master Table)'!C40, "") | B10: =IF('Data (Master Table)'!$B40 = $K$1, 'Data (Master Table)'!D40, "") | C10: =IF('Data (Master Table)'!$B40 = $K$1, 'Data (Master Table)'!E40, "") | D10: =IF('Data (Master Table)'!$B40 = $K$1, 'Data (Master Table)'!F40, "") | E10: =IF('Data (Master Table)'!$B40 = $K$1, 'Data (Master Table)'!G40, "") | F10: =IF('Data (Master Table)'!$B40 = $K$1, 'Data (Master Table)'!H40, "") | G10: =IF('Data (Master Table)'!$B40 = $K$1, 'Data (Master Table)'!I40, "") | H10: =IF('Data (Master Table)'!$B40 = $K$1, 'Data (Master Table)'!J40, "") | ... J10: =IF('Data (Master Table)'!$B40 = $K$1, 'Data (Master Table)'!L40, "") | O10: Work in progress:
A11: =IF('Data (Master Table)'!$B41 = $K$1, 'Data (Master Table)'!C41, "") | B11: =IF('Data (Master Table)'!$B41 = $K$1, 'Data (Master Table)'!D41, "") | C11: =IF('Data (Master Table)'!$B41 = $K$1, 'Data (Master Table)'!E41, "") | D11: =IF('Data (Master Table)'!$B41 = $K$1, 'Data (Master Table)'!F41, "") | E11: =IF('Data (Master Table)'!$B41 = $K$1, 'Data (Master Table)'!G41, "") | F11: =IF('Data (Master Table)'!$B41 = $K$1, 'Data (Master Table)'!H41, "") | G11: =IF('Data (Master Table)'!$B41 = $K$1, 'Data (Master Table)'!I41, "") | H11: =IF('Data (Master Table)'!$B41 = $K$1, 'Data (Master Table)'!J41, "") | ... J11: =IF('Data (Master Table)'!$B41 = $K$1, 'Data (Master Table)'!L41, "")
A12: =IF('Data (Master Table)'!$B42 = $K$1, 'Data (Master Table)'!C42, "") | B12: =IF('Data (Master Table)'!$B42 = $K$1, 'Data (Master Table)'!D42, "") | C12: =IF('Data (Master Table)'!$B42 = $K$1, 'Data (Master Table)'!E42, "") | D12: =IF('Data (Master Table)'!$B42 = $K$1, 'Data (Master Table)'!F42, "") | E12: =IF('Data (Master Table)'!$B42 = $K$1, 'Data (Master Table)'!G42, "") | F12: =IF('Data (Master Table)'!$B42 = $K$1, 'Data (Master Table)'!H42, "") | G12: =IF('Data (Master Table)'!$B42 = $K$1, 'Data (Master Table)'!I42, "") | H12: =IF('Data (Master Table)'!$B42 = $K$1, 'Data (Master Table)'!J42, "") | ... J12: =IF('Data (Master Table)'!$B42 = $K$1, 'Data (Master Table)'!L42, "")
A13: =IF('Data (Master Table)'!$B43 = $K$1, 'Data (Master Table)'!C43, "") | B13: =IF('Data (Master Table)'!$B43 = $K$1, 'Data (Master Table)'!D43, "") | C13: =IF('Data (Master Table)'!$B43 = $K$1, 'Data (Master Table)'!E43, "") | D13: =IF('Data (Master Table)'!$B43 = $K$1, 'Data (Master Table)'!F43, "") | E13: =IF('Data (Master Table)'!$B43 = $K$1, 'Data (Master Table)'!G43, "") | F13: =IF('Data (Master Table)'!$B43 = $K$1, 'Data (Master Table)'!H43, "") | G13: =IF('Data (Master Table)'!$B43 = $K$1, 'Data (Master Table)'!I43, "") | H13: =IF('Data (Master Table)'!$B43 = $K$1, 'Data (Master Table)'!J43, "") | ... J13: =IF('Data (Master Table)'!$B43 = $K$1, 'Data (Master Table)'!L43, "")
A14: =IF('Data (Master Table)'!$B44 = $K$1, 'Data (Master Table)'!C44, "") | B14: =IF('Data (Master Table)'!$B44 = $K$1, 'Data (Master Table)'!D44, "") | C14: =IF('Data (Master Table)'!$B44 = $K$1, 'Data (Master Table)'!E44, "") | D14: =IF('Data (Master Table)'!$B44 = $K$1, 'Data (Master Table)'!F44, "") | E14: =IF('Data (Master Table)'!$B44 = $K$1, 'Data (Master Table)'!G44, "") | F14: =IF('Data (Master Table)'!$B44 = $K$1, 'Data (Master Table)'!H44, "") | G14: =IF('Data (Master Table)'!$B44 = $K$1, 'Data (Master Table)'!I44, "") | H14: =IF('Data (Master Table)'!$B44 = $K$1, 'Data (Master Table)'!J44, "") | ... J14: =IF('Data (Master Table)'!$B44 = $K$1, 'Data (Master Table)'!L44, "")
A15: =IF('Data (Master Table)'!$B45 = $K$1, 'Data (Master Table)'!C45, "") | B15: =IF('Data (Master Table)'!$B45 = $K$1, 'Data (Master Table)'!D45, "") | C15: =IF('Data (Master Table)'!$B45 = $K$1, 'Data (Master Table)'!E45, "") | D15: =IF('Data (Master Table)'!$B45 = $K$1, 'Data (Master Table)'!F45, "") | E15: =IF('Data (Master Table)'!$B45 = $K$1, 'Data (Master Table)'!G45, "") | F15: =IF('Data (Master Table)'!$B45 = $K$1, 'Data (Master Table)'!H45, "") | G15: =IF('Data (Master Table)'!$B45 = $K$1, 'Data (Master Table)'!I45, "") | H15: =IF('Data (Master Table)'!$B45 = $K$1, 'Data (Master Table)'!J45, "") | ... J15: =IF('Data (Master Table)'!$B45 = $K$1, 'Data (Master Table)'!L45, "")
A16: =IF('Data (Master Table)'!$B46 = $K$1, 'Data (Master Table)'!C46, "") | B16: =IF('Data (Master Table)'!$B46 = $K$1, 'Data (Master Table)'!D46, "") | C16: =IF('Data (Master Table)'!$B46 = $K$1, 'Data (Master Table)'!E46, "") | D16: =IF('Data (Master Table)'!$B46 = $K$1, 'Data (Master Table)'!F46, "") | E16: =IF('Data (Master Table)'!$B46 = $K$1, 'Data (Master Table)'!G46, "") | F16: =IF('Data (Master Table)'!$B46 = $K$1, 'Data (Master Table)'!H46, "") | G16: =IF('Data (Master Table)'!$B46 = $K$1, 'Data (Master Table)'!I46, "") | H16: =IF('Data (Master Table)'!$B46 = $K$1, 'Data (Master Table)'!J46, "") | ... J16: =IF('Data (Master Table)'!$B46 = $K$1, 'Data (Master Table)'!L46, "")
O19: 5) Ramadan challenge & iftar
P20: •

Sheet Building Teams & Leadership
A1: ULTIMATE AIM : DEVELOP LEADERSHIP TEAMS, ESPECIALLY VOLUNTEERS SLT Lead Amer | K1: ='Data (Master Table)'!W6 -> Building Teams & Leadership
A2: ='Data (Master Table)'!C2 -> IS VALID | B2: ='Data (Master Table)'!D2 -> SMART Outcome | C2: ='Data (Master Table)'!E2 -> Benefit | D2: ='Data (Master Table)'!F2 -> Starting Point / Baseline | E2: ='Data (Master Table)'!G2 -> Department | F2: ='Data (Master Table)'!H2 -> Reported to OPEX | G2: ='Data (Master Table)'!I2 -> Responsible Person | H2: ='Data (Master Table)'!J2 -> Risk Level | ... S2: ='Data (Master Table)'!U2 -> Notes
A3: =IF('Data (Master Table)'!$B48 = $K$1, 'Data (Master Table)'!C48, "") -> YES | B3: =IF('Data (Master Table)'!$B48 = $K$1, 'Data (Master Table)'!D48, "") -> Competence & compliance | C3: =IF('Data (Master Table)'!$B48 = $K$1, 'Data (Master Table)'!E48, "") -> Risk reduction; improved leadership | D3: =IF('Data (Master Table)'!$B48 = $K$1, 'Data (Master Table)'!F48, "") -> Partial ad-hoc training coverage | E3: =IF('Data (Master Table)'!$B48 = $K$1, 'Data (Master Table)'!G48, "") -> OPEX | F3: =IF('Data (Master Table)'!$B48 = $K$1, 'Data (Master Table)'!H48, "") -> End of March End of June End of Sept | G3: =IF('Data (Master Table)'!$B48 = $K$1, 'Data (Master Table)'!I48, "") -> Amer | H3: =IF('Data (Master Table)'!$B48 = $K$1, 'Data (Master Table)'!J48, "") -> Medium | ... J3: =IF('Data (Master Table)'!$B48 = $K$1, 'Data (Master Table)'!L48, "") -> 46203 | K3: Train all leads in leadership, governance & safeguarding | L3: 1 | M3: Book courses; track completion | N3: Yusra training starting 18/01/26 | O3: Leasdership development programme 8 half day sessions over 6-12 months | P3: In Progress | R3: 0.6 | S3: To reconvene after Ramadan. Traing resumed Fri 1st May. However poor attendance (6 delegetes) Agreed with trainer Shahid to consider hybrid delivery of next session to encourage more attendees. Online Zoom training delivered Sat 20th June successfully with 2 attendees including most Leads and some team members. Good feedback and training well received. Will speak to Shahid at Yusra training to see how this can be delivered for the remaining sessions. Recent online scheduled session July 18th postponed as trainer's wife unwell. To re-organise.
A4: =IF('Data (Master Table)'!$B49 = $K$1, 'Data (Master Table)'!C49, "") -> YES | B4: =IF('Data (Master Table)'!$B49 = $K$1, 'Data (Master Table)'!D49, "") -> Onboarding excellence | C4: =IF('Data (Master Table)'!$B49 = $K$1, 'Data (Master Table)'!E49, "") -> Faster integration; safety | D4: =IF('Data (Master Table)'!$B49 = $K$1, 'Data (Master Table)'!F49, "") -> Onboarding is informal | E4: =IF('Data (Master Table)'!$B49 = $K$1, 'Data (Master Table)'!G49, "") -> OPEX | F4: =IF('Data (Master Table)'!$B49 = $K$1, 'Data (Master Table)'!H49, "") -> End of March End of June End of Sept | G4: =IF('Data (Master Table)'!$B49 = $K$1, 'Data (Master Table)'!I49, "") -> Amer | H4: =IF('Data (Master Table)'!$B49 = $K$1, 'Data (Master Table)'!J49, "") -> Low | ... J4: =IF('Data (Master Table)'!$B49 = $K$1, 'Data (Master Table)'!L49, "") -> 46142 | K4: Structured induction pack and build a process to align volunteers to roles | L4: 5 | M4: Checklist; DBS; H&S; first aid; handbook | N4: Will need to liase with Ali to organise DBS, 1st Aid and staff handbook | O4: No communication from Ali regarding staff handbook | P4: In Progress | Q4: Ali has already DBS several leads. | R4: 0.3 | S4: Faridah has notified me of her stepping down from AEC duties including OPEX and Leads Utd from 30th March. Conversation with Shaffiq regarding Perkbox. Have messaged Br Behzat with proposal and is being considered. After further discussion, Perkbox has been parked as not enough interest generated for this platform. Flick still to be considered for recording of volunteer training and documentation. Spoken to Ali rearding taking over the helm of Leads Utd. Ali has now led a couple of meetings asking for monthly updates from the leads. Amer will coninue leading OPEX onboarding volunteers and organising training.
A5: =IF('Data (Master Table)'!$B50 = $K$1, 'Data (Master Table)'!C50, "") -> YES | B5: =IF('Data (Master Table)'!$B50 = $K$1, 'Data (Master Table)'!D50, "") -> Volunteer attraction and retention | C5: =IF('Data (Master Table)'!$B50 = $K$1, 'Data (Master Table)'!E50, "") -> Staff retention & morale | D5: =IF('Data (Master Table)'!$B50 = $K$1, 'Data (Master Table)'!F50, "") -> Volunteers praised by Leaders, Volunteer yearly event | E5: =IF('Data (Master Table)'!$B50 = $K$1, 'Data (Master Table)'!G50, "") -> OPEX | F5: =IF('Data (Master Table)'!$B50 = $K$1, 'Data (Master Table)'!H50, "") -> End of March End of June End of Sept | G5: =IF('Data (Master Table)'!$B50 = $K$1, 'Data (Master Table)'!I50, "") -> Amer | H5: =IF('Data (Master Table)'!$B50 = $K$1, 'Data (Master Table)'!J50, "") -> Medium | ... J5: =IF('Data (Master Table)'!$B50 = $K$1, 'Data (Master Table)'!L50, "") -> 46053 | K5: Volunteer recognition & retention programme. considering Perkbox and other reward schemes. | L5: 3 | M5: Badges/PerkBox Dinner/awards; Yusra training | N5: 1.Training starting 18.01.26 2. volunteer dinner to be arranged post ramadan 01.04.26 3. Badges/lanyards 30.03.26 | O5: Amer to arrange sponsors and speakers for post Ramadan volunteer dinner as per last year. Following a thank you dinner at AEC arranged by Shaffiq and Shazli, I have separated the Leads award ceremony into the 'MOscars' to be held in the first week in April or first week of June. Families of leads to also be invited to acknowledge their support in the process. | P5: In Progress | Q5: We did see some new voliunteers sign up at Ramadan but these were drated in the 'Ramadan group' headed by Br Tauffique and Br Shazli who are notably not part of Leads Utd and contunues to be a bone of contention. | R5: 0.8 | S5: sponsors to include Abrahams, Cuppa Chai, Langthorne Pharmacy, Garden Square Denta, Kayi Crossfit. MOSCARS Lead Volunteer awards ceremony delivered successfully. Some excellent feedback from this especially with encoragement for youth memebers. Consideration for these youth members to form a youth council or shadow directors committee. Afsor has stepped back from youth activitie for now due to personal reasons. Will need to organise youth board meeting.
A6: =IF('Data (Master Table)'!$B51 = $K$1, 'Data (Master Table)'!C51, "") -> YES | B6: =IF('Data (Master Table)'!$B51 = $K$1, 'Data (Master Table)'!D51, "") -> Improved performance in key areas | C6: =IF('Data (Master Table)'!$B51 = $K$1, 'Data (Master Table)'!E51, "") -> Make important functions work better, prevent burnout | D6: =IF('Data (Master Table)'!$B51 = $K$1, 'Data (Master Table)'!F51, "") -> Digital, Marketing and Outreach teams limited human resources | E6: =IF('Data (Master Table)'!$B51 = $K$1, 'Data (Master Table)'!G51, "") -> OPEX | F6: =IF('Data (Master Table)'!$B51 = $K$1, 'Data (Master Table)'!H51, "") -> End of March End of June End of Sept | G6: =IF('Data (Master Table)'!$B51 = $K$1, 'Data (Master Table)'!I51, "") -> Amer | H6: =IF('Data (Master Table)'!$B51 = $K$1, 'Data (Master Table)'!J51, "") -> High | ... J6: =IF('Data (Master Table)'!$B51 = $K$1, 'Data (Master Table)'!L51, "") -> 46203 | K6: Increase volunteers in Digital, Marketing and Outreach Teams | L6: 3 | M6: Role profiles; mentoring; appraisal process | N6: Volunteer drive during Ramadan | O6: Request Imam to advertise volunteer rercuitment during Ramadan | P6: In Progress | Q6: Imam has his own ideasabout volunteer training. He has run some Zoom online training session pre-Ramadan. | R6: 0.5 | S6: Imam Ossama had mentioned volunteers for Ramadan at Jummah Khutbah . After the departure of Imam Ossama we have not as yet led a volunteer drive but individiual gropups are reaching out to theoir own networks to recruit eg dawah project Ahmed Rawi. Still need top recruit further for SEND Tech team, and Scouts following imminent departure of Saira who is currently Lead.
A7: =IF('Data (Master Table)'!$B52 = $K$1, 'Data (Master Table)'!C52, "") | B7: =IF('Data (Master Table)'!$B52 = $K$1, 'Data (Master Table)'!D52, "") | C7: =IF('Data (Master Table)'!$B52 = $K$1, 'Data (Master Table)'!E52, "") | D7: =IF('Data (Master Table)'!$B52 = $K$1, 'Data (Master Table)'!F52, "") | E7: =IF('Data (Master Table)'!$B52 = $K$1, 'Data (Master Table)'!G52, "") | F7: =IF('Data (Master Table)'!$B52 = $K$1, 'Data (Master Table)'!H52, "") | G7: =IF('Data (Master Table)'!$B52 = $K$1, 'Data (Master Table)'!I52, "") | H7: =IF('Data (Master Table)'!$B52 = $K$1, 'Data (Master Table)'!J52, "") | ... J7: =IF('Data (Master Table)'!$B52 = $K$1, 'Data (Master Table)'!L52, "")
A8: =IF('Data (Master Table)'!$B53 = $K$1, 'Data (Master Table)'!C53, "") | B8: =IF('Data (Master Table)'!$B53 = $K$1, 'Data (Master Table)'!D53, "") | C8: =IF('Data (Master Table)'!$B53 = $K$1, 'Data (Master Table)'!E53, "") | D8: =IF('Data (Master Table)'!$B53 = $K$1, 'Data (Master Table)'!F53, "") | E8: =IF('Data (Master Table)'!$B53 = $K$1, 'Data (Master Table)'!G53, "") | F8: =IF('Data (Master Table)'!$B53 = $K$1, 'Data (Master Table)'!H53, "") | G8: =IF('Data (Master Table)'!$B53 = $K$1, 'Data (Master Table)'!I53, "") | H8: =IF('Data (Master Table)'!$B53 = $K$1, 'Data (Master Table)'!J53, "") | ... J8: =IF('Data (Master Table)'!$B53 = $K$1, 'Data (Master Table)'!L53, "")
A9: =IF('Data (Master Table)'!$B54 = $K$1, 'Data (Master Table)'!C54, "") | B9: =IF('Data (Master Table)'!$B54 = $K$1, 'Data (Master Table)'!D54, "") | C9: =IF('Data (Master Table)'!$B54 = $K$1, 'Data (Master Table)'!E54, "") | D9: =IF('Data (Master Table)'!$B54 = $K$1, 'Data (Master Table)'!F54, "") | E9: =IF('Data (Master Table)'!$B54 = $K$1, 'Data (Master Table)'!G54, "") | F9: =IF('Data (Master Table)'!$B54 = $K$1, 'Data (Master Table)'!H54, "") | G9: =IF('Data (Master Table)'!$B54 = $K$1, 'Data (Master Table)'!I54, "") | H9: =IF('Data (Master Table)'!$B54 = $K$1, 'Data (Master Table)'!J54, "") | ... J9: =IF('Data (Master Table)'!$B54 = $K$1, 'Data (Master Table)'!L54, "")
A10: =IF('Data (Master Table)'!$B55 = $K$1, 'Data (Master Table)'!C55, "") | B10: =IF('Data (Master Table)'!$B55 = $K$1, 'Data (Master Table)'!D55, "") | C10: =IF('Data (Master Table)'!$B55 = $K$1, 'Data (Master Table)'!E55, "") | D10: =IF('Data (Master Table)'!$B55 = $K$1, 'Data (Master Table)'!F55, "") | E10: =IF('Data (Master Table)'!$B55 = $K$1, 'Data (Master Table)'!G55, "") | F10: =IF('Data (Master Table)'!$B55 = $K$1, 'Data (Master Table)'!H55, "") | G10: =IF('Data (Master Table)'!$B55 = $K$1, 'Data (Master Table)'!I55, "") | H10: =IF('Data (Master Table)'!$B55 = $K$1, 'Data (Master Table)'!J55, "") | ... J10: =IF('Data (Master Table)'!$B55 = $K$1, 'Data (Master Table)'!L55, "")
A11: =IF('Data (Master Table)'!$B56 = $K$1, 'Data (Master Table)'!C56, "") | B11: =IF('Data (Master Table)'!$B56 = $K$1, 'Data (Master Table)'!D56, "") | C11: =IF('Data (Master Table)'!$B56 = $K$1, 'Data (Master Table)'!E56, "") | D11: =IF('Data (Master Table)'!$B56 = $K$1, 'Data (Master Table)'!F56, "") | E11: =IF('Data (Master Table)'!$B56 = $K$1, 'Data (Master Table)'!G56, "") | F11: =IF('Data (Master Table)'!$B56 = $K$1, 'Data (Master Table)'!H56, "") | G11: =IF('Data (Master Table)'!$B56 = $K$1, 'Data (Master Table)'!I56, "") | H11: =IF('Data (Master Table)'!$B56 = $K$1, 'Data (Master Table)'!J56, "") | ... J11: =IF('Data (Master Table)'!$B56 = $K$1, 'Data (Master Table)'!L56, "")
